Workbook

Sheet My Portfolio
A1: MY PORTFOLIO — ALL OPTION TRADES: CASH-SECURED PUTS & COVERED CALLS
A2: One row per option you sell. Type = Put or Call (blank counts as Put). Yellow cells are yours to fill. When a trade ends, enter Close Date (+ Buy-back/C if you bought it back) — Realized P&L calculates itself. Rolled? Give the old and new rows the same Roll ID.
A3: Capital budget ($): | D3: 50000 | F3: Monthly target ($): | I3: 2000 | K3: <- type your own account size and monthly premium goal
A4: Total Premium | C4: Realized P&L | E4: Open Premium | G4: Cash at Risk (puts) | I4: Budget Left | K4: Open Puts | M4: Open Calls · Shares | O4: Closed Trades | Q4: Win Rate (closed) | S4: Broker-basis P&L
A5: =SUMPRODUCT($G$7:$G$106,$F$7:$F$106) | C5: =SUM($T$7:$T$106) | E5: =SUMPRODUCT(($M$7:$M$106="")*($B$7:$B$106<>"")*$G$7:$G$106*$F$7:$F$106) | G5: =SUMIFS($H$7:$H$106,$M$7:$M$106,"",$B$7:$B$106,"<>") | I5: =$D$3-SUMIFS($H$7:$H$106,$M$7:$M$106,"",$B$7:$B$106,"<>") | K5: =COUNTIFS($B$7:$B$106,"<>",$M$7:$M$106,"",$C$7:$C$106,"<>Call") | M5: =COUNTIFS($B$7:$B$106,"<>",$M$7:$M$106,"",$C$7:$C$106,"Call")&" · "&TEXT(SUMIFS($I$7:$I$106,$M$7:$M$106,"",$B$7:$B$106,"<>"),"#,##0")&" sh" | O5: =COUNTIFS($T$7:$T$106,">0")+COUNTIFS($T$7:$T$106,"<=0") | Q5: =IFERROR(COUNTIFS($T$7:$T$106,">0")/(COUNTIFS($T$7:$T$106,">0")+COUNTIFS($T$7:$T$106,"<=0")),"—") | S5: =SUM($P$7:$P$106)
A6: # | B6: Ticker | C6: Type | D6: Company | E6: Strike | F6: Contr | G6: Premium/C ($ per contract) | H6: Capital (cash, puts) | I6: Shares Locked (calls) | J6: Entry Date | K6: Expiry | L6: Status | M6: Close Date | N6: Buy-back/C ($ per contract) | O6: Fees | P6: Realized P&L (per leg, broker) | Q6: Ann. Return | R6: Notes | S6: Roll ID (same ID = one roll) | T6: Booked P&L (rolls deferred) | U6: Roll Net Credit (open roll leg)
A7: 1 | H7: =IF(OR(E7="",F7="",C7="Call"),"",E7*100*F7) | I7: =IF(AND(C7="Call",F7<>""),F7*100,"") | P7: =IF(OR(B7="",M7=""),"",(N(G7)-N(N7))*N(F7)-N(O7)) | Q7: =IF(OR(P7="",E7="",F7="",J7=""),"",P7/(E7*100*F7)*365/MAX(1,M7-J7)) | T7: =IF(P7="","",IF(TRIM(S7)="",P7,IF(AND(COUNTIFS($S$7:$S$106,S7,$M$7:$M$106,"",$B$7:$B$106,"<>")=0,COUNTIFS($S$7:$S$106,S7,$M$7:$M$106,">"&M7)=0,COUNTIFS($S$7:$S$106,S7,$M$7:$M$106,M7,$A$7:$A$106,">"&A7)=0),SUMIFS($P$7:$P$106,$S$7:$S$106,S7),""))) | U7: =IF(OR(TRIM(S7)="",B7="",M7<>""),"",N(G7)*N(F7)+SUMIFS($P$7:$P$106,$S$7:$S$106,S7))
A8: 2 | H8: =IF(OR(E8="",F8="",C8="Call"),"",E8*100*F8) | I8: =IF(AND(C8="Call",F8<>""),F8*100,"") | P8: =IF(OR(B8="",M8=""),"",(N(G8)-N(N8))*N(F8)-N(O8)) | Q8: =IF(OR(P8="",E8="",F8="",J8=""),"",P8/(E8*100*F8)*365/MAX(1,M8-J8)) | T8: =IF(P8="","",IF(TRIM(S8)="",P8,IF(AND(COUNTIFS($S$7:$S$106,S8,$M$7:$M$106,"",$B$7:$B$106,"<>")=0,COUNTIFS($S$7:$S$106,S8,$M$7:$M$106,">"&M8)=0,COUNTIFS($S$7:$S$106,S8,$M$7:$M$106,M8,$A$7:$A$106,">"&A8)=0),SUMIFS($P$7:$P$106,$S$7:$S$106,S8),""))) | U8: =IF(OR(TRIM(S8)="",B8="",M8<>""),"",N(G8)*N(F8)+SUMIFS($P$7:$P$106,$S$7:$S$106,S8))
A9: 3 | H9: =IF(OR(E9="",F9="",C9="Call"),"",E9*100*F9) | I9: =IF(AND(C9="Call",F9<>""),F9*100,"") | P9: =IF(OR(B9="",M9=""),"",(N(G9)-N(N9))*N(F9)-N(O9)) | Q9: =IF(OR(P9="",E9="",F9="",J9=""),"",P9/(E9*100*F9)*365/MAX(1,M9-J9)) | T9: =IF(P9="","",IF(TRIM(S9)="",P9,IF(AND(COUNTIFS($S$7:$S$106,S9,$M$7:$M$106,"",$B$7:$B$106,"<>")=0,COUNTIFS($S$7:$S$106,S9,$M$7:$M$106,">"&M9)=0,COUNTIFS($S$7:$S$106,S9,$M$7:$M$106,M9,$A$7:$A$106,">"&A9)=0),SUMIFS($P$7:$P$106,$S$7:$S$106,S9),""))) | U9: =IF(OR(TRIM(S9)="",B9="",M9<>""),"",N(G9)*N(F9)+SUMIFS($P$7:$P$106,$S$7:$S$106,S9))
A10: 4 | H10: =IF(OR(E10="",F10="",C10="Call"),"",E10*100*F10) | I10: =IF(AND(C10="Call",F10<>""),F10*100,"") | P10: =IF(OR(B10="",M10=""),"",(N(G10)-N(N10))*N(F10)-N(O10)) | Q10: =IF(OR(P10="",E10="",F10="",J10=""),"",P10/(E10*100*F10)*365/MAX(1,M10-J10)) | T10: =IF(P10="","",IF(TRIM(S10)="",P10,IF(AND(COUNTIFS($S$7:$S$106,S10,$M$7:$M$106,"",$B$7:$B$106,"<>")=0,COUNTIFS($S$7:$S$106,S10,$M$7:$M$106,">"&M10)=0,COUNTIFS($S$7:$S$106,S10,$M$7:$M$106,M10,$A$7:$A$106,">"&A10)=0),SUMIFS($P$7:$P$106,$S$7:$S$106,S10),""))) | U10: =IF(OR(TRIM(S10)="",B10="",M10<>""),"",N(G10)*N(F10)+SUMIFS($P$7:$P$106,$S$7:$S$106,S10))
A11: 5 | H11: =IF(OR(E11="",F11="",C11="Call"),"",E11*100*F11) | I11: =IF(AND(C11="Call",F11<>""),F11*100,"") | P11: =IF(OR(B11="",M11=""),"",(N(G11)-N(N11))*N(F11)-N(O11)) | Q11: =IF(OR(P11="",E11="",F11="",J11=""),"",P11/(E11*100*F11)*365/MAX(1,M11-J11)) | T11: =IF(P11="","",IF(TRIM(S11)="",P11,IF(AND(COUNTIFS($S$7:$S$106,S11,$M$7:$M$106,"",$B$7:$B$106,"<>")=0,COUNTIFS($S$7:$S$106,S11,$M$7:$M$106,">"&M11)=0,COUNTIFS($S$7:$S$106,S11,$M$7:$M$106,M11,$A$7:$A$106,">"&A11)=0),SUMIFS($P$7:$P$106,$S$7:$S$106,S11),""))) | U11: =IF(OR(TRIM(S11)="",B11="",M11<>""),"",N(G11)*N(F11)+SUMIFS($P$7:$P$106,$S$7:$S$106,S11))
A12: 6 | H12: =IF(OR(E12="",F12="",C12="Call"),"",E12*100*F12) | I12: =IF(AND(C12="Call",F12<>""),F12*100,"") | P12: =IF(OR(B12="",M12=""),"",(N(G12)-N(N12))*N(F12)-N(O12)) | Q12: =IF(OR(P12="",E12="",F12="",J12=""),"",P12/(E12*100*F12)*365/MAX(1,M12-J12)) | T12: =IF(P12="","",IF(TRIM(S12)="",P12,IF(AND(COUNTIFS($S$7:$S$106,S12,$M$7:$M$106,"",$B$7:$B$106,"<>")=0,COUNTIFS($S$7:$S$106,S12,$M$7:$M$106,">"&M12)=0,COUNTIFS($S$7:$S$106,S12,$M$7:$M$106,M12,$A$7:$A$106,">"&A12)=0),SUMIFS($P$7:$P$106,$S$7:$S$106,S12),""))) | U12: =IF(OR(TRIM(S12)="",B12="",M12<>""),"",N(G12)*N(F12)+SUMIFS($P$7:$P$106,$S$7:$S$106,S12))
A13: 7 | H13: =IF(OR(E13="",F13="",C13="Call"),"",E13*100*F13) | I13: =IF(AND(C13="Call",F13<>""),F13*100,"") | P13: =IF(OR(B13="",M13=""),"",(N(G13)-N(N13))*N(F13)-N(O13)) | Q13: =IF(OR(P13="",E13="",F13="",J13=""),"",P13/(E13*100*F13)*365/MAX(1,M13-J13)) | T13: =IF(P13="","",IF(TRIM(S13)="",P13,IF(AND(COUNTIFS($S$7:$S$106,S13,$M$7:$M$106,"",$B$7:$B$106,"<>")=0,COUNTIFS($S$7:$S$106,S13,$M$7:$M$106,">"&M13)=0,COUNTIFS($S$7:$S$106,S13,$M$7:$M$106,M13,$A$7:$A$106,">"&A13)=0),SUMIFS($P$7:$P$106,$S$7:$S$106,S13),""))) | U13: =IF(OR(TRIM(S13)="",B13="",M13<>""),"",N(G13)*N(F13)+SUMIFS($P$7:$P$106,$S$7:$S$106,S13))
A14: 8 | H14: =IF(OR(E14="",F14="",C14="Call"),"",E14*100*F14) | I14: =IF(AND(C14="Call",F14<>""),F14*100,"") | P14: =IF(OR(B14="",M14=""),"",(N(G14)-N(N14))*N(F14)-N(O14)) | Q14: =IF(OR(P14="",E14="",F14="",J14=""),"",P14/(E14*100*F14)*365/MAX(1,M14-J14)) | T14: =IF(P14="","",IF(TRIM(S14)="",P14,IF(AND(COUNTIFS($S$7:$S$106,S14,$M$7:$M$106,"",$B$7:$B$106,"<>")=0,COUNTIFS($S$7:$S$106,S14,$M$7:$M$106,">"&M14)=0,COUNTIFS($S$7:$S$106,S14,$M$7:$M$106,M14,$A$7:$A$106,">"&A14)=0),SUMIFS($P$7:$P$106,$S$7:$S$106,S14),""))) | U14: =IF(OR(TRIM(S14)="",B14="",M14<>""),"",N(G14)*N(F14)+SUMIFS($P$7:$P$106,$S$7:$S$106,S14))
A15: 9 | H15: =IF(OR(E15="",F15="",C15="Call"),"",E15*100*F15) | I15: =IF(AND(C15="Call",F15<>""),F15*100,"") | P15: =IF(OR(B15="",M15=""),"",(N(G15)-N(N15))*N(F15)-N(O15)) | Q15: =IF(OR(P15="",E15="",F15="",J15=""),"",P15/(E15*100*F15)*365/MAX(1,M15-J15)) | T15: =IF(P15="","",IF(TRIM(S15)="",P15,IF(AND(COUNTIFS($S$7:$S$106,S15,$M$7:$M$106,"",$B$7:$B$106,"<>")=0,COUNTIFS($S$7:$S$106,S15,$M$7:$M$106,">"&M15)=0,COUNTIFS($S$7:$S$106,S15,$M$7:$M$106,M15,$A$7:$A$106,">"&A15)=0),SUMIFS($P$7:$P$106,$S$7:$S$106,S15),""))) | U15: =IF(OR(TRIM(S15)="",B15="",M15<>""),"",N(G15)*N(F15)+SUMIFS($P$7:$P$106,$S$7:$S$106,S15))
A16: 10 | H16: =IF(OR(E16="",F16="",C16="Call"),"",E16*100*F16) | I16: =IF(AND(C16="Call",F16<>""),F16*100,"") | P16: =IF(OR(B16="",M16=""),"",(N(G16)-N(N16))*N(F16)-N(O16)) | Q16: =IF(OR(P16="",E16="",F16="",J16=""),"",P16/(E16*100*F16)*365/MAX(1,M16-J16)) | T16: =IF(P16="","",IF(TRIM(S16)="",P16,IF(AND(COUNTIFS($S$7:$S$106,S16,$M$7:$M$106,"",$B$7:$B$106,"<>")=0,COUNTIFS($S$7:$S$106,S16,$M$7:$M$106,">"&M16)=0,COUNTIFS($S$7:$S$106,S16,$M$7:$M$106,M16,$A$7:$A$106,">"&A16)=0),SUMIFS($P$7:$P$106,$S$7:$S$106,S16),""))) | U16: =IF(OR(TRIM(S16)="",B16="",M16<>""),"",N(G16)*N(F16)+SUMIFS($P$7:$P$106,$S$7:$S$106,S16))
A17: 11 | H17: =IF(OR(E17="",F17="",C17="Call"),"",E17*100*F17) | I17: =IF(AND(C17="Call",F17<>""),F17*100,"") | P17: =IF(OR(B17="",M17=""),"",(N(G17)-N(N17))*N(F17)-N(O17)) | Q17: =IF(OR(P17="",E17="",F17="",J17=""),"",P17/(E17*100*F17)*365/MAX(1,M17-J17)) | T17: =IF(P17="","",IF(TRIM(S17)="",P17,IF(AND(COUNTIFS($S$7:$S$106,S17,$M$7:$M$106,"",$B$7:$B$106,"<>")=0,COUNTIFS($S$7:$S$106,S17,$M$7:$M$106,">"&M17)=0,COUNTIFS($S$7:$S$106,S17,$M$7:$M$106,M17,$A$7:$A$106,">"&A17)=0),SUMIFS($P$7:$P$106,$S$7:$S$106,S17),""))) | U17: =IF(OR(TRIM(S17)="",B17="",M17<>""),"",N(G17)*N(F17)+SUMIFS($P$7:$P$106,$S$7:$S$106,S17))
A18: 12 | H18: =IF(OR(E18="",F18="",C18="Call"),"",E18*100*F18) | I18: =IF(AND(C18="Call",F18<>""),F18*100,"") | P18: =IF(OR(B18="",M18=""),"",(N(G18)-N(N18))*N(F18)-N(O18)) | Q18: =IF(OR(P18="",E18="",F18="",J18=""),"",P18/(E18*100*F18)*365/MAX(1,M18-J18)) | T18: =IF(P18="","",IF(TRIM(S18)="",P18,IF(AND(COUNTIFS($S$7:$S$106,S18,$M$7:$M$106,"",$B$7:$B$106,"<>")=0,COUNTIFS($S$7:$S$106,S18,$M$7:$M$106,">"&M18)=0,COUNTIFS($S$7:$S$106,S18,$M$7:$M$106,M18,$A$7:$A$106,">"&A18)=0),SUMIFS($P$7:$P$106,$S$7:$S$106,S18),""))) | U18: =IF(OR(TRIM(S18)="",B18="",M18<>""),"",N(G18)*N(F18)+SUMIFS($P$7:$P$106,$S$7:$S$106,S18))
... A106: 100 | H106: =IF(OR(E106="",F106="",C106="Call"),"",E106*100*F106) | I106: =IF(AND(C106="Call",F106<>""),F106*100,"") | P106: =IF(OR(B106="",M106=""),"",(N(G106)-N(N106))*N(F106)-N(O106)) | Q106: =IF(OR(P106="",E106="",F106="",J106=""),"",P106/(E106*100*F106)*365/MAX(1,M106-J106)) | T106: =IF(P106="","",IF(TRIM(S106)="",P106,IF(AND(COUNTIFS($S$7:$S$106,S106,$M$7:$M$106,"",$B$7:$B$106,"<>")=0,COUNTIFS($S$7:$S$106,S106,$M$7:$M$106,">"&M106)=0,COUNTIFS($S$7:$S$106,S106,$M$7:$M$106,M106,$A$7:$A$106,">"&A106)=0),SUMIFS($P$7:$P$106,$S$7:$S$106,S106),""))) | U106: =IF(OR(TRIM(S106)="",B106="",M106<>""),"",N(G106)*N(F106)+SUMIFS($P$7:$P$106,$S$7:$S$106,S106))
A107: TOTALS | G107: =SUMPRODUCT(G7:G106,F7:F106) | H107: =SUMIFS(H7:H106,M7:M106,"",B7:B106,"<>") | I107: =SUMIFS(I7:I106,M7:M106,"",B7:B106,"<>") | P107: =SUM(P7:P106) | T107: =SUM(T7:T106)
A109: HOW TO RECORD A TRADE (Type: Put / Call · Status: Open / Expired / Closed / Assigned / Rolled):
A110: • Sold a cash-secured put → Type = Put. Capital (strike × 100 × contracts) counts against your cash budget.
A111: • Sold a covered call → Type = Call. Needs 100 shares per contract (Shares Locked); it does NOT use cash budget. Keep the shares themselves in your US market share portfolio.
A112: • Expired worthless → Status = Expired, Close Date = expiry date, leave Buy-back blank. You keep the full premium.
A113: • Bought back early → Status = Closed, Close Date = date you closed, Buy-back/C = price paid × 100 (e.g. $3.00 → 300).
A114: • Assigned → Status = Assigned, Close Date = assignment date, Buy-back blank. Realized P&L = premium kept only. Put assigned: you now own the shares. Call assigned: your shares were sold at the strike — record that share gain/loss in your share portfolio, not here.
A115: • Rolled → close this row (Status = Rolled, Close Date = roll date, Buy-back/C = real cost to buy back × 100), log the new option as a NEW row, and type the SAME Roll ID on both (e.g. CRDO-1; keep it on every later roll of that position).
A116: Roll ID effect: the legs' P&L is held back (Booked P&L blank) until the last leg closes, then the whole chain lands in that month. Roll Net Credit on the open leg = total credit left after buy-backs; break-even = Strike − Net Credit ÷ (100 × Contr). Broker-basis P&L card = per-leg P&L the way your broker / tax statement shows it.
A117: Red Close Date = earlier than Entry Date (check the year). Amber Status = says Open but has a Close Date. Results by month / quarter / year: Monthly Summary tab. Not financial advice.

Sheet Monthly Summary
A1: MONTHLY SUMMARY — ACTUAL RESULTS (PUTS & COVERED CALLS)
A2: From Jan 2026. Realized P&L counts in the month a trade CLOSED (a roll chain: the month its LAST leg closed); Premium Opened = premium from options sold that month, less roll buy-backs (= net credit). YTD = running total within the year. Target = monthly target in My Portfolio cell I3. Updates automatically from My Portfolio.
A4: Period | B4: Put Premium Opened | C4: Call Premium Opened | D4: Put Realized P&L | E4: Call Realized P&L | F4: Total Realized P&L | G4: YTD Realized P&L | H4: Closed | I4: Wins | J4: Target | K4: vs Target | L4: Status
A5: 46023 | B5: =SUMPRODUCT(('My Portfolio'!$J$7:$J$106>=$A5)*('My Portfolio'!$J$7:$J$106<=EOMONTH($A5,0))*('My Portfolio'!$C$7:$C$106<>"Call")*'My Portfolio'!$G$7:$G$106*'My Portfolio'!$F$7:$F$106)-SUMPRODUCT(('My Portfolio'!$M$7:$M$106>=$A5)*('My Portfolio'!$M$7:$M$106<=EOMONTH($A5,0))*('My Portfolio'!$C$7:$C$106<>"Call")*(TRIM('My Portfolio'!$S$7:$S$106)<>"")*('My Portfolio'!$T$7:$T$106="")*'My Portfolio'!$N$7:$N$106*'My Portfolio'!$F$7:$F$106) | C5: =SUMPRODUCT(('My Portfolio'!$J$7:$J$106>=$A5)*('My Portfolio'!$J$7:$J$106<=EOMONTH($A5,0))*('My Portfolio'!$C$7:$C$106="Call")*'My Portfolio'!$G$7:$G$106*'My Portfolio'!$F$7:$F$106)-SUMPRODUCT(('My Portfolio'!$M$7:$M$106>=$A5)*('My Portfolio'!$M$7:$M$106<=EOMONTH($A5,0))*('My Portfolio'!$C$7:$C$106="Call")*(TRIM('My Portfolio'!$S$7:$S$106)<>"")*('My Portfolio'!$T$7:$T$106="")*'My Portfolio'!$N$7:$N$106*'My Portfolio'!$F$7:$F$106) | D5: =SUMIFS('My Portfolio'!$T$7:$T$106,'My Portfolio'!$M$7:$M$106,">="&$A5,'My Portfolio'!$M$7:$M$106,"<="&EOMONTH($A5,0),'My Portfolio'!$C$7:$C$106,"<>Call") | E5: =SUMIFS('My Portfolio'!$T$7:$T$106,'My Portfolio'!$M$7:$M$106,">="&$A5,'My Portfolio'!$M$7:$M$106,"<="&EOMONTH($A5,0),'My Portfolio'!$C$7:$C$106,"Call") | F5: =D5+E5 | G5: =F5 | H5: =COUNTIFS('My Portfolio'!$M$7:$M$106,">="&$A5,'My Portfolio'!$M$7:$M$106,"<="&EOMONTH($A5,0),'My Portfolio'!$T$7:$T$106,">0")+COUNTIFS('My Portfolio'!$M$7:$M$106,">="&$A5,'My Portfolio'!$M$7:$M$106,"<="&EOMONTH($A5,0),'My Portfolio'!$T$7:$T$106,"<=0") | I5: =COUNTIFS('My Portfolio'!$M$7:$M$106,">="&$A5,'My Portfolio'!$M$7:$M$106,"<="&EOMONTH($A5,0),'My Portfolio'!$T$7:$T$106,">0") | J5: ='My Portfolio'!$I$3 | K5: =F5-J5 | L5: =IF($A5>TODAY(),"upcoming",IF(F5>=J5,"✓ target met",IF($A5=DATE(YEAR(TODAY()),MONTH(TODAY()),1),"in progress","below target")))
A6: 46054 | B6: =SUMPRODUCT(('My Portfolio'!$J$7:$J$106>=$A6)*('My Portfolio'!$J$7:$J$106<=EOMONTH($A6,0))*('My Portfolio'!$C$7:$C$106<>"Call")*'My Portfolio'!$G$7:$G$106*'My Portfolio'!$F$7:$F$106)-SUMPRODUCT(('My Portfolio'!$M$7:$M$106>=$A6)*('My Portfolio'!$M$7:$M$106<=EOMONTH($A6,0))*('My Portfolio'!$C$7:$C$106<>"Call")*(TRIM('My Portfolio'!$S$7:$S$106)<>"")*('My Portfolio'!$T$7:$T$106="")*'My Portfolio'!$N$7:$N$106*'My Portfolio'!$F$7:$F$106) | C6: =SUMPRODUCT(('My Portfolio'!$J$7:$J$106>=$A6)*('My Portfolio'!$J$7:$J$106<=EOMONTH($A6,0))*('My Portfolio'!$C$7:$C$106="Call")*'My Portfolio'!$G$7:$G$106*'My Portfolio'!$F$7:$F$106)-SUMPRODUCT(('My Portfolio'!$M$7:$M$106>=$A6)*('My Portfolio'!$M$7:$M$106<=EOMONTH($A6,0))*('My Portfolio'!$C$7:$C$106="Call")*(TRIM('My Portfolio'!$S$7:$S$106)<>"")*('My Portfolio'!$T$7:$T$106="")*'My Portfolio'!$N$7:$N$106*'My Portfolio'!$F$7:$F$106) | D6: =SUMIFS('My Portfolio'!$T$7:$T$106,'My Portfolio'!$M$7:$M$106,">="&$A6,'My Portfolio'!$M$7:$M$106,"<="&EOMONTH($A6,0),'My Portfolio'!$C$7:$C$106,"<>Call") | E6: =SUMIFS('My Portfolio'!$T$7:$T$106,'My Portfolio'!$M$7:$M$106,">="&$A6,'My Portfolio'!$M$7:$M$106,"<="&EOMONTH($A6,0),'My Portfolio'!$C$7:$C$106,"Call") | F6: =D6+E6 | G6: =G5+F6 | H6: =COUNTIFS('My Portfolio'!$M$7:$M$106,">="&$A6,'My Portfolio'!$M$7:$M$106,"<="&EOMONTH($A6,0),'My Portfolio'!$T$7:$T$106,">0")+COUNTIFS('My Portfolio'!$M$7:$M$106,">="&$A6,'My Portfolio'!$M$7:$M$106,"<="&EOMONTH($A6,0),'My Portfolio'!$T$7:$T$106,"<=0") | I6: =COUNTIFS('My Portfolio'!$M$7:$M$106,">="&$A6,'My Portfolio'!$M$7:$M$106,"<="&EOMONTH($A6,0),'My Portfolio'!$T$7:$T$106,">0") | J6: ='My Portfolio'!$I$3 | K6: =F6-J6 | L6: =IF($A6>TODAY(),"upcoming",IF(F6>=J6,"✓ target met",IF($A6=DATE(YEAR(TODAY()),MONTH(TODAY()),1),"in progress","below target")))
A7: 46082 | B7: =SUMPRODUCT(('My Portfolio'!$J$7:$J$106>=$A7)*('My Portfolio'!$J$7:$J$106<=EOMONTH($A7,0))*('My Portfolio'!$C$7:$C$106<>"Call")*'My Portfolio'!$G$7:$G$106*'My Portfolio'!$F$7:$F$106)-SUMPRODUCT(('My Portfolio'!$M$7:$M$106>=$A7)*('My Portfolio'!$M$7:$M$106<=EOMONTH($A7,0))*('My Portfolio'!$C$7:$C$106<>"Call")*(TRIM('My Portfolio'!$S$7:$S$106)<>"")*('My Portfolio'!$T$7:$T$106="")*'My Portfolio'!$N$7:$N$106*'My Portfolio'!$F$7:$F$106) | C7: =SUMPRODUCT(('My Portfolio'!$J$7:$J$106>=$A7)*('My Portfolio'!$J$7:$J$106<=EOMONTH($A7,0))*('My Portfolio'!$C$7:$C$106="Call")*'My Portfolio'!$G$7:$G$106*'My Portfolio'!$F$7:$F$106)-SUMPRODUCT(('My Portfolio'!$M$7:$M$106>=$A7)*('My Portfolio'!$M$7:$M$106<=EOMONTH($A7,0))*('My Portfolio'!$C$7:$C$106="Call")*(TRIM('My Portfolio'!$S$7:$S$106)<>"")*('My Portfolio'!$T$7:$T$106="")*'My Portfolio'!$N$7:$N$106*'My Portfolio'!$F$7:$F$106) | D7: =SUMIFS('My Portfolio'!$T$7:$T$106,'My Portfolio'!$M$7:$M$106,">="&$A7,'My Portfolio'!$M$7:$M$106,"<="&EOMONTH($A7,0),'My Portfolio'!$C$7:$C$106,"<>Call") | E7: =SUMIFS('My Portfolio'!$T$7:$T$106,'My Portfolio'!$M$7:$M$106,">="&$A7,'My Portfolio'!$M$7:$M$106,"<="&EOMONTH($A7,0),'My Portfolio'!$C$7:$C$106,"Call") | F7: =D7+E7 | G7: =G6+F7 | H7: =COUNTIFS('My Portfolio'!$M$7:$M$106,">="&$A7,'My Portfolio'!$M$7:$M$106,"<="&EOMONTH($A7,0),'My Portfolio'!$T$7:$T$106,">0")+COUNTIFS('My Portfolio'!$M$7:$M$106,">="&$A7,'My Portfolio'!$M$7:$M$106,"<="&EOMONTH($A7,0),'My Portfolio'!$T$7:$T$106,"<=0") | I7: =COUNTIFS('My Portfolio'!$M$7:$M$106,">="&$A7,'My Portfolio'!$M$7:$M$106,"<="&EOMONTH($A7,0),'My Portfolio'!$T$7:$T$106,">0") | J7: ='My Portfolio'!$I$3 | K7: =F7-J7 | L7: =IF($A7>TODAY(),"upcoming",IF(F7>=J7,"✓ target met",IF($A7=DATE(YEAR(TODAY()),MONTH(TODAY()),1),"in progress","below target")))
A8: Q1 2026 | B8: =B5+B6+B7 | C8: =C5+C6+C7 | D8: =D5+D6+D7 | E8: =E5+E6+E7 | F8: =F5+F6+F7 | G8: =G7 | H8: =H5+H6+H7 | I8: =I5+I6+I7 | J8: =IF(A5<=TODAY(),J5,0)+IF(A6<=TODAY(),J6,0)+IF(A7<=TODAY(),J7,0) | K8: =F8-J8 | L8: =IF(A5>TODAY(),"upcoming",IF(F8>=J8,"✓ target met",IF(A7>=DATE(YEAR(TODAY()),MONTH(TODAY()),1),"in progress","below target")))
A9: 46113 | B9: =SUMPRODUCT(('My Portfolio'!$J$7:$J$106>=$A9)*('My Portfolio'!$J$7:$J$106<=EOMONTH($A9,0))*('My Portfolio'!$C$7:$C$106<>"Call")*'My Portfolio'!$G$7:$G$106*'My Portfolio'!$F$7:$F$106)-SUMPRODUCT(('My Portfolio'!$M$7:$M$106>=$A9)*('My Portfolio'!$M$7:$M$106<=EOMONTH($A9,0))*('My Portfolio'!$C$7:$C$106<>"Call")*(TRIM('My Portfolio'!$S$7:$S$106)<>"")*('My Portfolio'!$T$7:$T$106="")*'My Portfolio'!$N$7:$N$106*'My Portfolio'!$F$7:$F$106) | C9: =SUMPRODUCT(('My Portfolio'!$J$7:$J$106>=$A9)*('My Portfolio'!$J$7:$J$106<=EOMONTH($A9,0))*('My Portfolio'!$C$7:$C$106="Call")*'My Portfolio'!$G$7:$G$106*'My Portfolio'!$F$7:$F$106)-SUMPRODUCT(('My Portfolio'!$M$7:$M$106>=$A9)*('My Portfolio'!$M$7:$M$106<=EOMONTH($A9,0))*('My Portfolio'!$C$7:$C$106="Call")*(TRIM('My Portfolio'!$S$7:$S$106)<>"")*('My Portfolio'!$T$7:$T$106="")*'My Portfolio'!$N$7:$N$106*'My Portfolio'!$F$7:$F$106) | D9: =SUMIFS('My Portfolio'!$T$7:$T$106,'My Portfolio'!$M$7:$M$106,">="&$A9,'My Portfolio'!$M$7:$M$106,"<="&EOMONTH($A9,0),'My Portfolio'!$C$7:$C$106,"<>Call") | E9: =SUMIFS('My Portfolio'!$T$7:$T$106,'My Portfolio'!$M$7:$M$106,">="&$A9,'My Portfolio'!$M$7:$M$106,"<="&EOMONTH($A9,0),'My Portfolio'!$C$7:$C$106,"Call") | F9: =D9+E9 | G9: =G7+F9 | H9: =COUNTIFS('My Portfolio'!$M$7:$M$106,">="&$A9,'My Portfolio'!$M$7:$M$106,"<="&EOMONTH($A9,0),'My Portfolio'!$T$7:$T$106,">0")+COUNTIFS('My Portfolio'!$M$7:$M$106,">="&$A9,'My Portfolio'!$M$7:$M$106,"<="&EOMONTH($A9,0),'My Portfolio'!$T$7:$T$106,"<=0") | I9: =COUNTIFS('My Portfolio'!$M$7:$M$106,">="&$A9,'My Portfolio'!$M$7:$M$106,"<="&EOMONTH($A9,0),'My Portfolio'!$T$7:$T$106,">0") | J9: ='My Portfolio'!$I$3 | K9: =F9-J9 | L9: =IF($A9>TODAY(),"upcoming",IF(F9>=J9,"✓ target met",IF($A9=DATE(YEAR(TODAY()),MONTH(TODAY()),1),"in progress","below target")))
A10: 46143 | B10: =SUMPRODUCT(('My Portfolio'!$J$7:$J$106>=$A10)*('My Portfolio'!$J$7:$J$106<=EOMONTH($A10,0))*('My Portfolio'!$C$7:$C$106<>"Call")*'My Portfolio'!$G$7:$G$106*'My Portfolio'!$F$7:$F$106)-SUMPRODUCT(('My Portfolio'!$M$7:$M$106>=$A10)*('My Portfolio'!$M$7:$M$106<=EOMONTH($A10,0))*('My Portfolio'!$C$7:$C$106<>"Call")*(TRIM('My Portfolio'!$S$7:$S$106)<>"")*('My Portfolio'!$T$7:$T$106="")*'My Portfolio'!$N$7:$N$106*'My Portfolio'!$F$7:$F$106) | C10: =SUMPRODUCT(('My Portfolio'!$J$7:$J$106>=$A10)*('My Portfolio'!$J$7:$J$106<=EOMONTH($A10,0))*('My Portfolio'!$C$7:$C$106="Call")*'My Portfolio'!$G$7:$G$106*'My Portfolio'!$F$7:$F$106)-SUMPRODUCT(('My Portfolio'!$M$7:$M$106>=$A10)*('My Portfolio'!$M$7:$M$106<=EOMONTH($A10,0))*('My Portfolio'!$C$7:$C$106="Call")*(TRIM('My Portfolio'!$S$7:$S$106)<>"")*('My Portfolio'!$T$7:$T$106="")*'My Portfolio'!$N$7:$N$106*'My Portfolio'!$F$7:$F$106) | D10: =SUMIFS('My Portfolio'!$T$7:$T$106,'My Portfolio'!$M$7:$M$106,">="&$A10,'My Portfolio'!$M$7:$M$106,"<="&EOMONTH($A10,0),'My Portfolio'!$C$7:$C$106,"<>Call") | E10: =SUMIFS('My Portfolio'!$T$7:$T$106,'My Portfolio'!$M$7:$M$106,">="&$A10,'My Portfolio'!$M$7:$M$106,"<="&EOMONTH($A10,0),'My Portfolio'!$C$7:$C$106,"Call") | F10: =D10+E10 | G10: =G9+F10 | H10: =COUNTIFS('My Portfolio'!$M$7:$M$106,">="&$A10,'My Portfolio'!$M$7:$M$106,"<="&EOMONTH($A10,0),'My Portfolio'!$T$7:$T$106,">0")+COUNTIFS('My Portfolio'!$M$7:$M$106,">="&$A10,'My Portfolio'!$M$7:$M$106,"<="&EOMONTH($A10,0),'My Portfolio'!$T$7:$T$106,"<=0") | I10: =COUNTIFS('My Portfolio'!$M$7:$M$106,">="&$A10,'My Portfolio'!$M$7:$M$106,"<="&EOMONTH($A10,0),'My Portfolio'!$T$7:$T$106,">0") | J10: ='My Portfolio'!$I$3 | K10: =F10-J10 | L10: =IF($A10>TODAY(),"upcoming",IF(F10>=J10,"✓ target met",IF($A10=DATE(YEAR(TODAY()),MONTH(TODAY()),1),"in progress","below target")))
A11: 46174 | B11: =SUMPRODUCT(('My Portfolio'!$J$7:$J$106>=$A11)*('My Portfolio'!$J$7:$J$106<=EOMONTH($A11,0))*('My Portfolio'!$C$7:$C$106<>"Call")*'My Portfolio'!$G$7:$G$106*'My Portfolio'!$F$7:$F$106)-SUMPRODUCT(('My Portfolio'!$M$7:$M$106>=$A11)*('My Portfolio'!$M$7:$M$106<=EOMONTH($A11,0))*('My Portfolio'!$C$7:$C$106<>"Call")*(TRIM('My Portfolio'!$S$7:$S$106)<>"")*('My Portfolio'!$T$7:$T$106="")*'My Portfolio'!$N$7:$N$106*'My Portfolio'!$F$7:$F$106) | C11: =SUMPRODUCT(('My Portfolio'!$J$7:$J$106>=$A11)*('My Portfolio'!$J$7:$J$106<=EOMONTH($A11,0))*('My Portfolio'!$C$7:$C$106="Call")*'My Portfolio'!$G$7:$G$106*'My Portfolio'!$F$7:$F$106)-SUMPRODUCT(('My Portfolio'!$M$7:$M$106>=$A11)*('My Portfolio'!$M$7:$M$106<=EOMONTH($A11,0))*('My Portfolio'!$C$7:$C$106="Call")*(TRIM('My Portfolio'!$S$7:$S$106)<>"")*('My Portfolio'!$T$7:$T$106="")*'My Portfolio'!$N$7:$N$106*'My Portfolio'!$F$7:$F$106) | D11: =SUMIFS('My Portfolio'!$T$7:$T$106,'My Portfolio'!$M$7:$M$106,">="&$A11,'My Portfolio'!$M$7:$M$106,"<="&EOMONTH($A11,0),'My Portfolio'!$C$7:$C$106,"<>Call") | E11: =SUMIFS('My Portfolio'!$T$7:$T$106,'My Portfolio'!$M$7:$M$106,">="&$A11,'My Portfolio'!$M$7:$M$106,"<="&EOMONTH($A11,0),'My Portfolio'!$C$7:$C$106,"Call") | F11: =D11+E11 | G11: =G10+F11 | H11: =COUNTIFS('My Portfolio'!$M$7:$M$106,">="&$A11,'My Portfolio'!$M$7:$M$106,"<="&EOMONTH($A11,0),'My Portfolio'!$T$7:$T$106,">0")+COUNTIFS('My Portfolio'!$M$7:$M$106,">="&$A11,'My Portfolio'!$M$7:$M$106,"<="&EOMONTH($A11,0),'My Portfolio'!$T$7:$T$106,"<=0") | I11: =COUNTIFS('My Portfolio'!$M$7:$M$106,">="&$A11,'My Portfolio'!$M$7:$M$106,"<="&EOMONTH($A11,0),'My Portfolio'!$T$7:$T$106,">0") | J11: ='My Portfolio'!$I$3 | K11: =F11-J11 | L11: =IF($A11>TODAY(),"upcoming",IF(F11>=J11,"✓ target met",IF($A11=DATE(YEAR(TODAY()),MONTH(TODAY()),1),"in progress","below target")))
A12: Q2 2026 | B12: =B9+B10+B11 | C12: =C9+C10+C11 | D12: =D9+D10+D11 | E12: =E9+E10+E11 | F12: =F9+F10+F11 | G12: =G11 | H12: =H9+H10+H11 | I12: =I9+I10+I11 | J12: =IF(A9<=TODAY(),J9,0)+IF(A10<=TODAY(),J10,0)+IF(A11<=TODAY(),J11,0) | K12: =F12-J12 | L12: =IF(A9>TODAY(),"upcoming",IF(F12>=J12,"✓ target met",IF(A11>=DATE(YEAR(TODAY()),MONTH(TODAY()),1),"in progress","below target")))
A13: 46204 | B13: =SUMPRODUCT(('My Portfolio'!$J$7:$J$106>=$A13)*('My Portfolio'!$J$7:$J$106<=EOMONTH($A13,0))*('My Portfolio'!$C$7:$C$106<>"Call")*'My Portfolio'!$G$7:$G$106*'My Portfolio'!$F$7:$F$106)-SUMPRODUCT(('My Portfolio'!$M$7:$M$106>=$A13)*('My Portfolio'!$M$7:$M$106<=EOMONTH($A13,0))*('My Portfolio'!$C$7:$C$106<>"Call")*(TRIM('My Portfolio'!$S$7:$S$106)<>"")*('My Portfolio'!$T$7:$T$106="")*'My Portfolio'!$N$7:$N$106*'My Portfolio'!$F$7:$F$106) | C13: =SUMPRODUCT(('My Portfolio'!$J$7:$J$106>=$A13)*('My Portfolio'!$J$7:$J$106<=EOMONTH($A13,0))*('My Portfolio'!$C$7:$C$106="Call")*'My Portfolio'!$G$7:$G$106*'My Portfolio'!$F$7:$F$106)-SUMPRODUCT(('My Portfolio'!$M$7:$M$106>=$A13)*('My Portfolio'!$M$7:$M$106<=EOMONTH($A13,0))*('My Portfolio'!$C$7:$C$106="Call")*(TRIM('My Portfolio'!$S$7:$S$106)<>"")*('My Portfolio'!$T$7:$T$106="")*'My Portfolio'!$N$7:$N$106*'My Portfolio'!$F$7:$F$106) | D13: =SUMIFS('My Portfolio'!$T$7:$T$106,'My Portfolio'!$M$7:$M$106,">="&$A13,'My Portfolio'!$M$7:$M$106,"<="&EOMONTH($A13,0),'My Portfolio'!$C$7:$C$106,"<>Call") | E13: =SUMIFS('My Portfolio'!$T$7:$T$106,'My Portfolio'!$M$7:$M$106,">="&$A13,'My Portfolio'!$M$7:$M$106,"<="&EOMONTH($A13,0),'My Portfolio'!$C$7:$C$106,"Call") | F13: =D13+E13 | G13: =G11+F13 | H13: =COUNTIFS('My Portfolio'!$M$7:$M$106,">="&$A13,'My Portfolio'!$M$7:$M$106,"<="&EOMONTH($A13,0),'My Portfolio'!$T$7:$T$106,">0")+COUNTIFS('My Portfolio'!$M$7:$M$106,">="&$A13,'My Portfolio'!$M$7:$M$106,"<="&EOMONTH($A13,0),'My Portfolio'!$T$7:$T$106,"<=0") | I13: =COUNTIFS('My Portfolio'!$M$7:$M$106,">="&$A13,'My Portfolio'!$M$7:$M$106,"<="&EOMONTH($A13,0),'My Portfolio'!$T$7:$T$106,">0") | J13: ='My Portfolio'!$I$3 | K13: =F13-J13 | L13: =IF($A13>TODAY(),"upcoming",IF(F13>=J13,"✓ target met",IF($A13=DATE(YEAR(TODAY()),MONTH(TODAY()),1),"in progress","below target")))
A14: 46235 | B14: =SUMPRODUCT(('My Portfolio'!$J$7:$J$106>=$A14)*('My Portfolio'!$J$7:$J$106<=EOMONTH($A14,0))*('My Portfolio'!$C$7:$C$106<>"Call")*'My Portfolio'!$G$7:$G$106*'My Portfolio'!$F$7:$F$106)-SUMPRODUCT(('My Portfolio'!$M$7:$M$106>=$A14)*('My Portfolio'!$M$7:$M$106<=EOMONTH($A14,0))*('My Portfolio'!$C$7:$C$106<>"Call")*(TRIM('My Portfolio'!$S$7:$S$106)<>"")*('My Portfolio'!$T$7:$T$106="")*'My Portfolio'!$N$7:$N$106*'My Portfolio'!$F$7:$F$106) | C14: =SUMPRODUCT(('My Portfolio'!$J$7:$J$106>=$A14)*('My Portfolio'!$J$7:$J$106<=EOMONTH($A14,0))*('My Portfolio'!$C$7:$C$106="Call")*'My Portfolio'!$G$7:$G$106*'My Portfolio'!$F$7:$F$106)-SUMPRODUCT(('My Portfolio'!$M$7:$M$106>=$A14)*('My Portfolio'!$M$7:$M$106<=EOMONTH($A14,0))*('My Portfolio'!$C$7:$C$106="Call")*(TRIM('My Portfolio'!$S$7:$S$106)<>"")*('My Portfolio'!$T$7:$T$106="")*'My Portfolio'!$N$7:$N$106*'My Portfolio'!$F$7:$F$106) | D14: =SUMIFS('My Portfolio'!$T$7:$T$106,'My Portfolio'!$M$7:$M$106,">="&$A14,'My Portfolio'!$M$7:$M$106,"<="&EOMONTH($A14,0),'My Portfolio'!$C$7:$C$106,"<>Call") | E14: =SUMIFS('My Portfolio'!$T$7:$T$106,'My Portfolio'!$M$7:$M$106,">="&$A14,'My Portfolio'!$M$7:$M$106,"<="&EOMONTH($A14,0),'My Portfolio'!$C$7:$C$106,"Call") | F14: =D14+E14 | G14: =G13+F14 | H14: =COUNTIFS('My Portfolio'!$M$7:$M$106,">="&$A14,'My Portfolio'!$M$7:$M$106,"<="&EOMONTH($A14,0),'My Portfolio'!$T$7:$T$106,">0")+COUNTIFS('My Portfolio'!$M$7:$M$106,">="&$A14,'My Portfolio'!$M$7:$M$106,"<="&EOMONTH($A14,0),'My Portfolio'!$T$7:$T$106,"<=0") | I14: =COUNTIFS('My Portfolio'!$M$7:$M$106,">="&$A14,'My Portfolio'!$M$7:$M$106,"<="&EOMONTH($A14,0),'My Portfolio'!$T$7:$T$106,">0") | J14: ='My Portfolio'!$I$3 | K14: =F14-J14 | L14: =IF($A14>TODAY(),"upcoming",IF(F14>=J14,"✓ target met",IF($A14=DATE(YEAR(TODAY()),MONTH(TODAY()),1),"in progress","below target")))
A15: 46266 | B15: =SUMPRODUCT(('My Portfolio'!$J$7:$J$106>=$A15)*('My Portfolio'!$J$7:$J$106<=EOMONTH($A15,0))*('My Portfolio'!$C$7:$C$106<>"Call")*'My Portfolio'!$G$7:$G$106*'My Portfolio'!$F$7:$F$106)-SUMPRODUCT(('My Portfolio'!$M$7:$M$106>=$A15)*('My Portfolio'!$M$7:$M$106<=EOMONTH($A15,0))*('My Portfolio'!$C$7:$C$106<>"Call")*(TRIM('My Portfolio'!$S$7:$S$106)<>"")*('My Portfolio'!$T$7:$T$106="")*'My Portfolio'!$N$7:$N$106*'My Portfolio'!$F$7:$F$106) | C15: =SUMPRODUCT(('My Portfolio'!$J$7:$J$106>=$A15)*('My Portfolio'!$J$7:$J$106<=EOMONTH($A15,0))*('My Portfolio'!$C$7:$C$106="Call")*'My Portfolio'!$G$7:$G$106*'My Portfolio'!$F$7:$F$106)-SUMPRODUCT(('My Portfolio'!$M$7:$M$106>=$A15)*('My Portfolio'!$M$7:$M$106<=EOMONTH($A15,0))*('My Portfolio'!$C$7:$C$106="Call")*(TRIM('My Portfolio'!$S$7:$S$106)<>"")*('My Portfolio'!$T$7:$T$106="")*'My Portfolio'!$N$7:$N$106*'My Portfolio'!$F$7:$F$106) | D15: =SUMIFS('My Portfolio'!$T$7:$T$106,'My Portfolio'!$M$7:$M$106,">="&$A15,'My Portfolio'!$M$7:$M$106,"<="&EOMONTH($A15,0),'My Portfolio'!$C$7:$C$106,"<>Call") | E15: =SUMIFS('My Portfolio'!$T$7:$T$106,'My Portfolio'!$M$7:$M$106,">="&$A15,'My Portfolio'!$M$7:$M$106,"<="&EOMONTH($A15,0),'My Portfolio'!$C$7:$C$106,"Call") | F15: =D15+E15 | G15: =G14+F15 | H15: =COUNTIFS('My Portfolio'!$M$7:$M$106,">="&$A15,'My Portfolio'!$M$7:$M$106,"<="&EOMONTH($A15,0),'My Portfolio'!$T$7:$T$106,">0")+COUNTIFS('My Portfolio'!$M$7:$M$106,">="&$A15,'My Portfolio'!$M$7:$M$106,"<="&EOMONTH($A15,0),'My Portfolio'!$T$7:$T$106,"<=0") | I15: =COUNTIFS('My Portfolio'!$M$7:$M$106,">="&$A15,'My Portfolio'!$M$7:$M$106,"<="&EOMONTH($A15,0),'My Portfolio'!$T$7:$T$106,">0") | J15: ='My Portfolio'!$I$3 | K15: =F15-J15 | L15: =IF($A15>TODAY(),"upcoming",IF(F15>=J15,"✓ target met",IF($A15=DATE(YEAR(TODAY()),MONTH(TODAY()),1),"in progress","below target")))
A16: Q3 2026 | B16: =B13+B14+B15 | C16: =C13+C14+C15 | D16: =D13+D14+D15 | E16: =E13+E14+E15 | F16: =F13+F14+F15 | G16: =G15 | H16: =H13+H14+H15 | I16: =I13+I14+I15 | J16: =IF(A13<=TODAY(),J13,0)+IF(A14<=TODAY(),J14,0)+IF(A15<=TODAY(),J15,0) | K16: =F16-J16 | L16: =IF(A13>TODAY(),"upcoming",IF(F16>=J16,"✓ target met",IF(A15>=DATE(YEAR(TODAY()),MONTH(TODAY()),1),"in progress","below target")))
A17: 46296 | B17: =SUMPRODUCT(('My Portfolio'!$J$7:$J$106>=$A17)*('My Portfolio'!$J$7:$J$106<=EOMONTH($A17,0))*('My Portfolio'!$C$7:$C$106<>"Call")*'My Portfolio'!$G$7:$G$106*'My Portfolio'!$F$7:$F$106)-SUMPRODUCT(('My Portfolio'!$M$7:$M$106>=$A17)*('My Portfolio'!$M$7:$M$106<=EOMONTH($A17,0))*('My Portfolio'!$C$7:$C$106<>"Call")*(TRIM('My Portfolio'!$S$7:$S$106)<>"")*('My Portfolio'!$T$7:$T$106="")*'My Portfolio'!$N$7:$N$106*'My Portfolio'!$F$7:$F$106) | C17: =SUMPRODUCT(('My Portfolio'!$J$7:$J$106>=$A17)*('My Portfolio'!$J$7:$J$106<=EOMONTH($A17,0))*('My Portfolio'!$C$7:$C$106="Call")*'My Portfolio'!$G$7:$G$106*'My Portfolio'!$F$7:$F$106)-SUMPRODUCT(('My Portfolio'!$M$7:$M$106>=$A17)*('My Portfolio'!$M$7:$M$106<=EOMONTH($A17,0))*('My Portfolio'!$C$7:$C$106="Call")*(TRIM('My Portfolio'!$S$7:$S$106)<>"")*('My Portfolio'!$T$7:$T$106="")*'My Portfolio'!$N$7:$N$106*'My Portfolio'!$F$7:$F$106) | D17: =SUMIFS('My Portfolio'!$T$7:$T$106,'My Portfolio'!$M$7:$M$106,">="&$A17,'My Portfolio'!$M$7:$M$106,"<="&EOMONTH($A17,0),'My Portfolio'!$C$7:$C$106,"<>Call") | E17: =SUMIFS('My Portfolio'!$T$7:$T$106,'My Portfolio'!$M$7:$M$106,">="&$A17,'My Portfolio'!$M$7:$M$106,"<="&EOMONTH($A17,0),'My Portfolio'!$C$7:$C$106,"Call") | F17: =D17+E17 | G17: =G15+F17 | H17: =COUNTIFS('My Portfolio'!$M$7:$M$106,">="&$A17,'My Portfolio'!$M$7:$M$106,"<="&EOMONTH($A17,0),'My Portfolio'!$T$7:$T$106,">0")+COUNTIFS('My Portfolio'!$M$7:$M$106,">="&$A17,'My Portfolio'!$M$7:$M$106,"<="&EOMONTH($A17,0),'My Portfolio'!$T$7:$T$106,"<=0") | I17: =COUNTIFS('My Portfolio'!$M$7:$M$106,">="&$A17,'My Portfolio'!$M$7:$M$106,"<="&EOMONTH($A17,0),'My Portfolio'!$T$7:$T$106,">0") | J17: ='My Portfolio'!$I$3 | K17: =F17-J17 | L17: =IF($A17>TODAY(),"upcoming",IF(F17>=J17,"✓ target met",IF($A17=DATE(YEAR(TODAY()),MONTH(TODAY()),1),"in progress","below target")))
A18: 46327 | B18: =SUMPRODUCT(('My Portfolio'!$J$7:$J$106>=$A18)*('My Portfolio'!$J$7:$J$106<=EOMONTH($A18,0))*('My Portfolio'!$C$7:$C$106<>"Call")*'My Portfolio'!$G$7:$G$106*'My Portfolio'!$F$7:$F$106)-SUMPRODUCT(('My Portfolio'!$M$7:$M$106>=$A18)*('My Portfolio'!$M$7:$M$106<=EOMONTH($A18,0))*('My Portfolio'!$C$7:$C$106<>"Call")*(TRIM('My Portfolio'!$S$7:$S$106)<>"")*('My Portfolio'!$T$7:$T$106="")*'My Portfolio'!$N$7:$N$106*'My Portfolio'!$F$7:$F$106) | C18: =SUMPRODUCT(('My Portfolio'!$J$7:$J$106>=$A18)*('My Portfolio'!$J$7:$J$106<=EOMONTH($A18,0))*('My Portfolio'!$C$7:$C$106="Call")*'My Portfolio'!$G$7:$G$106*'My Portfolio'!$F$7:$F$106)-SUMPRODUCT(('My Portfolio'!$M$7:$M$106>=$A18)*('My Portfolio'!$M$7:$M$106<=EOMONTH($A18,0))*('My Portfolio'!$C$7:$C$106="Call")*(TRIM('My Portfolio'!$S$7:$S$106)<>"")*('My Portfolio'!$T$7:$T$106="")*'My Portfolio'!$N$7:$N$106*'My Portfolio'!$F$7:$F$106) | D18: =SUMIFS('My Portfolio'!$T$7:$T$106,'My Portfolio'!$M$7:$M$106,">="&$A18,'My Portfolio'!$M$7:$M$106,"<="&EOMONTH($A18,0),'My Portfolio'!$C$7:$C$106,"<>Call") | E18: =SUMIFS('My Portfolio'!$T$7:$T$106,'My Portfolio'!$M$7:$M$106,">="&$A18,'My Portfolio'!$M$7:$M$106,"<="&EOMONTH($A18,0),'My Portfolio'!$C$7:$C$106,"Call") | F18: =D18+E18 | G18: =G17+F18 | H18: =COUNTIFS('My Portfolio'!$M$7:$M$106,">="&$A18,'My Portfolio'!$M$7:$M$106,"<="&EOMONTH($A18,0),'My Portfolio'!$T$7:$T$106,">0")+COUNTIFS('My Portfolio'!$M$7:$M$106,">="&$A18,'My Portfolio'!$M$7:$M$106,"<="&EOMONTH($A18,0),'My Portfolio'!$T$7:$T$106,"<=0") | I18: =COUNTIFS('My Portfolio'!$M$7:$M$106,">="&$A18,'My Portfolio'!$M$7:$M$106,"<="&EOMONTH($A18,0),'My Portfolio'!$T$7:$T$106,">0") | J18: ='My Portfolio'!$I$3 | K18: =F18-J18 | L18: =IF($A18>TODAY(),"upcoming",IF(F18>=J18,"✓ target met",IF($A18=DATE(YEAR(TODAY()),MONTH(TODAY()),1),"in progress","below target")))
A19: 46357 | B19: =SUMPRODUCT(('My Portfolio'!$J$7:$J$106>=$A19)*('My Portfolio'!$J$7:$J$106<=EOMONTH($A19,0))*('My Portfolio'!$C$7:$C$106<>"Call")*'My Portfolio'!$G$7:$G$106*'My Portfolio'!$F$7:$F$106)-SUMPRODUCT(('My Portfolio'!$M$7:$M$106>=$A19)*('My Portfolio'!$M$7:$M$106<=EOMONTH($A19,0))*('My Portfolio'!$C$7:$C$106<>"Call")*(TRIM('My Portfolio'!$S$7:$S$106)<>"")*('My Portfolio'!$T$7:$T$106="")*'My Portfolio'!$N$7:$N$106*'My Portfolio'!$F$7:$F$106) | C19: =SUMPRODUCT(('My Portfolio'!$J$7:$J$106>=$A19)*('My Portfolio'!$J$7:$J$106<=EOMONTH($A19,0))*('My Portfolio'!$C$7:$C$106="Call")*'My Portfolio'!$G$7:$G$106*'My Portfolio'!$F$7:$F$106)-SUMPRODUCT(('My Portfolio'!$M$7:$M$106>=$A19)*('My Portfolio'!$M$7:$M$106<=EOMONTH($A19,0))*('My Portfolio'!$C$7:$C$106="Call")*(TRIM('My Portfolio'!$S$7:$S$106)<>"")*('My Portfolio'!$T$7:$T$106="")*'My Portfolio'!$N$7:$N$106*'My Portfolio'!$F$7:$F$106) | D19: =SUMIFS('My Portfolio'!$T$7:$T$106,'My Portfolio'!$M$7:$M$106,">="&$A19,'My Portfolio'!$M$7:$M$106,"<="&EOMONTH($A19,0),'My Portfolio'!$C$7:$C$106,"<>Call") | E19: =SUMIFS('My Portfolio'!$T$7:$T$106,'My Portfolio'!$M$7:$M$106,">="&$A19,'My Portfolio'!$M$7:$M$106,"<="&EOMONTH($A19,0),'My Portfolio'!$C$7:$C$106,"Call") | F19: =D19+E19 | G19: =G18+F19 | H19: =COUNTIFS('My Portfolio'!$M$7:$M$106,">="&$A19,'My Portfolio'!$M$7:$M$106,"<="&EOMONTH($A19,0),'My Portfolio'!$T$7:$T$106,">0")+COUNTIFS('My Portfolio'!$M$7:$M$106,">="&$A19,'My Portfolio'!$M$7:$M$106,"<="&EOMONTH($A19,0),'My Portfolio'!$T$7:$T$106,"<=0") | I19: =COUNTIFS('My Portfolio'!$M$7:$M$106,">="&$A19,'My Portfolio'!$M$7:$M$106,"<="&EOMONTH($A19,0),'My Portfolio'!$T$7:$T$106,">0") | J19: ='My Portfolio'!$I$3 | K19: =F19-J19 | L19: =IF($A19>TODAY(),"upcoming",IF(F19>=J19,"✓ target met",IF($A19=DATE(YEAR(TODAY()),MONTH(TODAY()),1),"in progress","below target")))
A20: Q4 2026 | B20: =B17+B18+B19 | C20: =C17+C18+C19 | D20: =D17+D18+D19 | E20: =E17+E18+E19 | F20: =F17+F18+F19 | G20: =G19 | H20: =H17+H18+H19 | I20: =I17+I18+I19 | J20: =IF(A17<=TODAY(),J17,0)+IF(A18<=TODAY(),J18,0)+IF(A19<=TODAY(),J19,0) | K20: =F20-J20 | L20: =IF(A17>TODAY(),"upcoming",IF(F20>=J20,"✓ target met",IF(A19>=DATE(YEAR(TODAY()),MONTH(TODAY()),1),"in progress","below target")))
A21: 2026 YTD | B21: =B5+B6+B7+B9+B10+B11+B13+B14+B15+B17+B18+B19 | C21: =C5+C6+C7+C9+C10+C11+C13+C14+C15+C17+C18+C19 | D21: =D5+D6+D7+D9+D10+D11+D13+D14+D15+D17+D18+D19 | E21: =E5+E6+E7+E9+E10+E11+E13+E14+E15+E17+E18+E19 | F21: =F5+F6+F7+F9+F10+F11+F13+F14+F15+F17+F18+F19 | G21: =G19 | H21: =H5+H6+H7+H9+H10+H11+H13+H14+H15+H17+H18+H19 | I21: =I5+I6+I7+I9+I10+I11+I13+I14+I15+I17+I18+I19 | J21: =IF(A5<=TODAY(),J5,0)+IF(A6<=TODAY(),J6,0)+IF(A7<=TODAY(),J7,0)+IF(A9<=TODAY(),J9,0)+IF(A10<=TODAY(),J10,0)+IF(A11<=TODAY(),J11,0)+IF(A13<=TODAY(),J13,0)+IF(A14<=TODAY(),J14,0)+IF(A15<=TODAY(),J15,0)+IF(A17<=TODAY(),J17,0)+IF(A18<=TODAY(),J18,0)+IF(A19<=TODAY(),J19,0) | K21: =F21-J21 | L21: =IF(A5>TODAY(),"upcoming",IF(F21>=J21,"✓ target met",IF(A19>=DATE(YEAR(TODAY()),MONTH(TODAY()),1),"in progress","below target")))
A22: 46388 | B22: =SUMPRODUCT(('My Portfolio'!$J$7:$J$106>=$A22)*('My Portfolio'!$J$7:$J$106<=EOMONTH($A22,0))*('My Portfolio'!$C$7:$C$106<>"Call")*'My Portfolio'!$G$7:$G$106*'My Portfolio'!$F$7:$F$106)-SUMPRODUCT(('My Portfolio'!$M$7:$M$106>=$A22)*('My Portfolio'!$M$7:$M$106<=EOMONTH($A22,0))*('My Portfolio'!$C$7:$C$106<>"Call")*(TRIM('My Portfolio'!$S$7:$S$106)<>"")*('My Portfolio'!$T$7:$T$106="")*'My Portfolio'!$N$7:$N$106*'My Portfolio'!$F$7:$F$106) | C22: =SUMPRODUCT(('My Portfolio'!$J$7:$J$106>=$A22)*('My Portfolio'!$J$7:$J$106<=EOMONTH($A22,0))*('My Portfolio'!$C$7:$C$106="Call")*'My Portfolio'!$G$7:$G$106*'My Portfolio'!$F$7:$F$106)-SUMPRODUCT(('My Portfolio'!$M$7:$M$106>=$A22)*('My Portfolio'!$M$7:$M$106<=EOMONTH($A22,0))*('My Portfolio'!$C$7:$C$106="Call")*(TRIM('My Portfolio'!$S$7:$S$106)<>"")*('My Portfolio'!$T$7:$T$106="")*'My Portfolio'!$N$7:$N$106*'My Portfolio'!$F$7:$F$106) | D22: =SUMIFS('My Portfolio'!$T$7:$T$106,'My Portfolio'!$M$7:$M$106,">="&$A22,'My Portfolio'!$M$7:$M$106,"<="&EOMONTH($A22,0),'My Portfolio'!$C$7:$C$106,"<>Call") | E22: =SUMIFS('My Portfolio'!$T$7:$T$106,'My Portfolio'!$M$7:$M$106,">="&$A22,'My Portfolio'!$M$7:$M$106,"<="&EOMONTH($A22,0),'My Portfolio'!$C$7:$C$106,"Call") | F22: =D22+E22 | G22: =F22 | H22: =COUNTIFS('My Portfolio'!$M$7:$M$106,">="&$A22,'My Portfolio'!$M$7:$M$106,"<="&EOMONTH($A22,0),'My Portfolio'!$T$7:$T$106,">0")+COUNTIFS('My Portfolio'!$M$7:$M$106,">="&$A22,'My Portfolio'!$M$7:$M$106,"<="&EOMONTH($A22,0),'My Portfolio'!$T$7:$T$106,"<=0") | I22: =COUNTIFS('My Portfolio'!$M$7:$M$106,">="&$A22,'My Portfolio'!$M$7:$M$106,"<="&EOMONTH($A22,0),'My Portfolio'!$T$7:$T$106,">0") | J22: ='My Portfolio'!$I$3 | K22: =F22-J22 | L22: =IF($A22>TODAY(),"upcoming",IF(F22>=J22,"✓ target met",IF($A22=DATE(YEAR(TODAY()),MONTH(TODAY()),1),"in progress","below target")))
A23: 46419 | B23: =SUMPRODUCT(('My Portfolio'!$J$7:$J$106>=$A23)*('My Portfolio'!$J$7:$J$106<=EOMONTH($A23,0))*('My Portfolio'!$C$7:$C$106<>"Call")*'My Portfolio'!$G$7:$G$106*'My Portfolio'!$F$7:$F$106)-SUMPRODUCT(('My Portfolio'!$M$7:$M$106>=$A23)*('My Portfolio'!$M$7:$M$106<=EOMONTH($A23,0))*('My Portfolio'!$C$7:$C$106<>"Call")*(TRIM('My Portfolio'!$S$7:$S$106)<>"")*('My Portfolio'!$T$7:$T$106="")*'My Portfolio'!$N$7:$N$106*'My Portfolio'!$F$7:$F$106) | C23: =SUMPRODUCT(('My Portfolio'!$J$7:$J$106>=$A23)*('My Portfolio'!$J$7:$J$106<=EOMONTH($A23,0))*('My Portfolio'!$C$7:$C$106="Call")*'My Portfolio'!$G$7:$G$106*'My Portfolio'!$F$7:$F$106)-SUMPRODUCT(('My Portfolio'!$M$7:$M$106>=$A23)*('My Portfolio'!$M$7:$M$106<=EOMONTH($A23,0))*('My Portfolio'!$C$7:$C$106="Call")*(TRIM('My Portfolio'!$S$7:$S$106)<>"")*('My Portfolio'!$T$7:$T$106="")*'My Portfolio'!$N$7:$N$106*'My Portfolio'!$F$7:$F$106) | D23: =SUMIFS('My Portfolio'!$T$7:$T$106,'My Portfolio'!$M$7:$M$106,">="&$A23,'My Portfolio'!$M$7:$M$106,"<="&EOMONTH($A23,0),'My Portfolio'!$C$7:$C$106,"<>Call") | E23: =SUMIFS('My Portfolio'!$T$7:$T$106,'My Portfolio'!$M$7:$M$106,">="&$A23,'My Portfolio'!$M$7:$M$106,"<="&EOMONTH($A23,0),'My Portfolio'!$C$7:$C$106,"Call") | F23: =D23+E23 | G23: =G22+F23 | H23: =COUNTIFS('My Portfolio'!$M$7:$M$106,">="&$A23,'My Portfolio'!$M$7:$M$106,"<="&EOMONTH($A23,0),'My Portfolio'!$T$7:$T$106,">0")+COUNTIFS('My Portfolio'!$M$7:$M$106,">="&$A23,'My Portfolio'!$M$7:$M$106,"<="&EOMONTH($A23,0),'My Portfolio'!$T$7:$T$106,"<=0") | I23: =COUNTIFS('My Portfolio'!$M$7:$M$106,">="&$A23,'My Portfolio'!$M$7:$M$106,"<="&EOMONTH($A23,0),'My Portfolio'!$T$7:$T$106,">0") | J23: ='My Portfolio'!$I$3 | K23: =F23-J23 | L23: =IF($A23>TODAY(),"upcoming",IF(F23>=J23,"✓ target met",IF($A23=DATE(YEAR(TODAY()),MONTH(TODAY()),1),"in progress","below target")))
A24: 46447 | B24: =SUMPRODUCT(('My Portfolio'!$J$7:$J$106>=$A24)*('My Portfolio'!$J$7:$J$106<=EOMONTH($A24,0))*('My Portfolio'!$C$7:$C$106<>"Call")*'My Portfolio'!$G$7:$G$106*'My Portfolio'!$F$7:$F$106)-SUMPRODUCT(('My Portfolio'!$M$7:$M$106>=$A24)*('My Portfolio'!$M$7:$M$106<=EOMONTH($A24,0))*('My Portfolio'!$C$7:$C$106<>"Call")*(TRIM('My Portfolio'!$S$7:$S$106)<>"")*('My Portfolio'!$T$7:$T$106="")*'My Portfolio'!$N$7:$N$106*'My Portfolio'!$F$7:$F$106) | C24: =SUMPRODUCT(('My Portfolio'!$J$7:$J$106>=$A24)*('My Portfolio'!$J$7:$J$106<=EOMONTH($A24,0))*('My Portfolio'!$C$7:$C$106="Call")*'My Portfolio'!$G$7:$G$106*'My Portfolio'!$F$7:$F$106)-SUMPRODUCT(('My Portfolio'!$M$7:$M$106>=$A24)*('My Portfolio'!$M$7:$M$106<=EOMONTH($A24,0))*('My Portfolio'!$C$7:$C$106="Call")*(TRIM('My Portfolio'!$S$7:$S$106)<>"")*('My Portfolio'!$T$7:$T$106="")*'My Portfolio'!$N$7:$N$106*'My Portfolio'!$F$7:$F$106) | D24: =SUMIFS('My Portfolio'!$T$7:$T$106,'My Portfolio'!$M$7:$M$106,">="&$A24,'My Portfolio'!$M$7:$M$106,"<="&EOMONTH($A24,0),'My Portfolio'!$C$7:$C$106,"<>Call") | E24: =SUMIFS('My Portfolio'!$T$7:$T$106,'My Portfolio'!$M$7:$M$106,">="&$A24,'My Portfolio'!$M$7:$M$106,"<="&EOMONTH($A24,0),'My Portfolio'!$C$7:$C$106,"Call") | F24: =D24+E24 | G24: =G23+F24 | H24: =COUNTIFS('My Portfolio'!$M$7:$M$106,">="&$A24,'My Portfolio'!$M$7:$M$106,"<="&EOMONTH($A24,0),'My Portfolio'!$T$7:$T$106,">0")+COUNTIFS('My Portfolio'!$M$7:$M$106,">="&$A24,'My Portfolio'!$M$7:$M$106,"<="&EOMONTH($A24,0),'My Portfolio'!$T$7:$T$106,"<=0") | I24: =COUNTIFS('My Portfolio'!$M$7:$M$106,">="&$A24,'My Portfolio'!$M$7:$M$106,"<="&EOMONTH($A24,0),'My Portfolio'!$T$7:$T$106,">0") | J24: ='My Portfolio'!$I$3 | K24: =F24-J24 | L24: =IF($A24>TODAY(),"upcoming",IF(F24>=J24,"✓ target met",IF($A24=DATE(YEAR(TODAY()),MONTH(TODAY()),1),"in progress","below target")))
A25: Q1 2027 | B25: =B22+B23+B24 | C25: =C22+C23+C24 | D25: =D22+D23+D24 | E25: =E22+E23+E24 | F25: =F22+F23+F24 | G25: =G24 | H25: =H22+H23+H24 | I25: =I22+I23+I24 | J25: =IF(A22<=TODAY(),J22,0)+IF(A23<=TODAY(),J23,0)+IF(A24<=TODAY(),J24,0) | K25: =F25-J25 | L25: =IF(A22>TODAY(),"upcoming",IF(F25>=J25,"✓ target met",IF(A24>=DATE(YEAR(TODAY()),MONTH(TODAY()),1),"in progress","below target")))
A26: 46478 | B26: =SUMPRODUCT(('My Portfolio'!$J$7:$J$106>=$A26)*('My Portfolio'!$J$7:$J$106<=EOMONTH($A26,0))*('My Portfolio'!$C$7:$C$106<>"Call")*'My Portfolio'!$G$7:$G$106*'My Portfolio'!$F$7:$F$106)-SUMPRODUCT(('My Portfolio'!$M$7:$M$106>=$A26)*('My Portfolio'!$M$7:$M$106<=EOMONTH($A26,0))*('My Portfolio'!$C$7:$C$106<>"Call")*(TRIM('My Portfolio'!$S$7:$S$106)<>"")*('My Portfolio'!$T$7:$T$106="")*'My Portfolio'!$N$7:$N$106*'My Portfolio'!$F$7:$F$106) | C26: =SUMPRODUCT(('My Portfolio'!$J$7:$J$106>=$A26)*('My Portfolio'!$J$7:$J$106<=EOMONTH($A26,0))*('My Portfolio'!$C$7:$C$106="Call")*'My Portfolio'!$G$7:$G$106*'My Portfolio'!$F$7:$F$106)-SUMPRODUCT(('My Portfolio'!$M$7:$M$106>=$A26)*('My Portfolio'!$M$7:$M$106<=EOMONTH($A26,0))*('My Portfolio'!$C$7:$C$106="Call")*(TRIM('My Portfolio'!$S$7:$S$106)<>"")*('My Portfolio'!$T$7:$T$106="")*'My Portfolio'!$N$7:$N$106*'My Portfolio'!$F$7:$F$106) | D26: =SUMIFS('My Portfolio'!$T$7:$T$106,'My Portfolio'!$M$7:$M$106,">="&$A26,'My Portfolio'!$M$7:$M$106,"<="&EOMONTH($A26,0),'My Portfolio'!$C$7:$C$106,"<>Call") | E26: =SUMIFS('My Portfolio'!$T$7:$T$106,'My Portfolio'!$M$7:$M$106,">="&$A26,'My Portfolio'!$M$7:$M$106,"<="&EOMONTH($A26,0),'My Portfolio'!$C$7:$C$106,"Call") | F26: =D26+E26 | G26: =G24+F26 | H26: =COUNTIFS('My Portfolio'!$M$7:$M$106,">="&$A26,'My Portfolio'!$M$7:$M$106,"<="&EOMONTH($A26,0),'My Portfolio'!$T$7:$T$106,">0")+COUNTIFS('My Portfolio'!$M$7:$M$106,">="&$A26,'My Portfolio'!$M$7:$M$106,"<="&EOMONTH($A26,0),'My Portfolio'!$T$7:$T$106,"<=0") | I26: =COUNTIFS('My Portfolio'!$M$7:$M$106,">="&$A26,'My Portfolio'!$M$7:$M$106,"<="&EOMONTH($A26,0),'My Portfolio'!$T$7:$T$106,">0") | J26: ='My Portfolio'!$I$3 | K26: =F26-J26 | L26: =IF($A26>TODAY(),"upcoming",IF(F26>=J26,"✓ target met",IF($A26=DATE(YEAR(TODAY()),MONTH(TODAY()),1),"in progress","below target")))
A27: 46508 | B27: =SUMPRODUCT(('My Portfolio'!$J$7:$J$106>=$A27)*('My Portfolio'!$J$7:$J$106<=EOMONTH($A27,0))*('My Portfolio'!$C$7:$C$106<>"Call")*'My Portfolio'!$G$7:$G$106*'My Portfolio'!$F$7:$F$106)-SUMPRODUCT(('My Portfolio'!$M$7:$M$106>=$A27)*('My Portfolio'!$M$7:$M$106<=EOMONTH($A27,0))*('My Portfolio'!$C$7:$C$106<>"Call")*(TRIM('My Portfolio'!$S$7:$S$106)<>"")*('My Portfolio'!$T$7:$T$106="")*'My Portfolio'!$N$7:$N$106*'My Portfolio'!$F$7:$F$106) | C27: =SUMPRODUCT(('My Portfolio'!$J$7:$J$106>=$A27)*('My Portfolio'!$J$7:$J$106<=EOMONTH($A27,0))*('My Portfolio'!$C$7:$C$106="Call")*'My Portfolio'!$G$7:$G$106*'My Portfolio'!$F$7:$F$106)-SUMPRODUCT(('My Portfolio'!$M$7:$M$106>=$A27)*('My Portfolio'!$M$7:$M$106<=EOMONTH($A27,0))*('My Portfolio'!$C$7:$C$106="Call")*(TRIM('My Portfolio'!$S$7:$S$106)<>"")*('My Portfolio'!$T$7:$T$106="")*'My Portfolio'!$N$7:$N$106*'My Portfolio'!$F$7:$F$106) | D27: =SUMIFS('My Portfolio'!$T$7:$T$106,'My Portfolio'!$M$7:$M$106,">="&$A27,'My Portfolio'!$M$7:$M$106,"<="&EOMONTH($A27,0),'My Portfolio'!$C$7:$C$106,"<>Call") | E27: =SUMIFS('My Portfolio'!$T$7:$T$106,'My Portfolio'!$M$7:$M$106,">="&$A27,'My Portfolio'!$M$7:$M$106,"<="&EOMONTH($A27,0),'My Portfolio'!$C$7:$C$106,"Call") | F27: =D27+E27 | G27: =G26+F27 | H27: =COUNTIFS('My Portfolio'!$M$7:$M$106,">="&$A27,'My Portfolio'!$M$7:$M$106,"<="&EOMONTH($A27,0),'My Portfolio'!$T$7:$T$106,">0")+COUNTIFS('My Portfolio'!$M$7:$M$106,">="&$A27,'My Portfolio'!$M$7:$M$106,"<="&EOMONTH($A27,0),'My Portfolio'!$T$7:$T$106,"<=0") | I27: =COUNTIFS('My Portfolio'!$M$7:$M$106,">="&$A27,'My Portfolio'!$M$7:$M$106,"<="&EOMONTH($A27,0),'My Portfolio'!$T$7:$T$106,">0") | J27: ='My Portfolio'!$I$3 | K27: =F27-J27 | L27: =IF($A27>TODAY(),"upcoming",IF(F27>=J27,"✓ target met",IF($A27=DATE(YEAR(TODAY()),MONTH(TODAY()),1),"in progress","below target")))
A28: 46539 | B28: =SUMPRODUCT(('My Portfolio'!$J$7:$J$106>=$A28)*('My Portfolio'!$J$7:$J$106<=EOMONTH($A28,0))*('My Portfolio'!$C$7:$C$106<>"Call")*'My Portfolio'!$G$7:$G$106*'My Portfolio'!$F$7:$F$106)-SUMPRODUCT(('My Portfolio'!$M$7:$M$106>=$A28)*('My Portfolio'!$M$7:$M$106<=EOMONTH($A28,0))*('My Portfolio'!$C$7:$C$106<>"Call")*(TRIM('My Portfolio'!$S$7:$S$106)<>"")*('My Portfolio'!$T$7:$T$106="")*'My Portfolio'!$N$7:$N$106*'My Portfolio'!$F$7:$F$106) | C28: =SUMPRODUCT(('My Portfolio'!$J$7:$J$106>=$A28)*('My Portfolio'!$J$7:$J$106<=EOMONTH($A28,0))*('My Portfolio'!$C$7:$C$106="Call")*'My Portfolio'!$G$7:$G$106*'My Portfolio'!$F$7:$F$106)-SUMPRODUCT(('My Portfolio'!$M$7:$M$106>=$A28)*('My Portfolio'!$M$7:$M$106<=EOMONTH($A28,0))*('My Portfolio'!$C$7:$C$106="Call")*(TRIM('My Portfolio'!$S$7:$S$106)<>"")*('My Portfolio'!$T$7:$T$106="")*'My Portfolio'!$N$7:$N$106*'My Portfolio'!$F$7:$F$106) | D28: =SUMIFS('My Portfolio'!$T$7:$T$106,'My Portfolio'!$M$7:$M$106,">="&$A28,'My Portfolio'!$M$7:$M$106,"<="&EOMONTH($A28,0),'My Portfolio'!$C$7:$C$106,"<>Call") | E28: =SUMIFS('My Portfolio'!$T$7:$T$106,'My Portfolio'!$M$7:$M$106,">="&$A28,'My Portfolio'!$M$7:$M$106,"<="&EOMONTH($A28,0),'My Portfolio'!$C$7:$C$106,"Call") | F28: =D28+E28 | G28: =G27+F28 | H28: =COUNTIFS('My Portfolio'!$M$7:$M$106,">="&$A28,'My Portfolio'!$M$7:$M$106,"<="&EOMONTH($A28,0),'My Portfolio'!$T$7:$T$106,">0")+COUNTIFS('My Portfolio'!$M$7:$M$106,">="&$A28,'My Portfolio'!$M$7:$M$106,"<="&EOMONTH($A28,0),'My Portfolio'!$T$7:$T$106,"<=0") | I28: =COUNTIFS('My Portfolio'!$M$7:$M$106,">="&$A28,'My Portfolio'!$M$7:$M$106,"<="&EOMONTH($A28,0),'My Portfolio'!$T$7:$T$106,">0") | J28: ='My Portfolio'!$I$3 | K28: =F28-J28 | L28: =IF($A28>TODAY(),"upcoming",IF(F28>=J28,"✓ target met",IF($A28=DATE(YEAR(TODAY()),MONTH(TODAY()),1),"in progress","below target")))
A29: Q2 2027 | B29: =B26+B27+B28 | C29: =C26+C27+C28 | D29: =D26+D27+D28 | E29: =E26+E27+E28 | F29: =F26+F27+F28 | G29: =G28 | H29: =H26+H27+H28 | I29: =I26+I27+I28 | J29: =IF(A26<=TODAY(),J26,0)+IF(A27<=TODAY(),J27,0)+IF(A28<=TODAY(),J28,0) | K29: =F29-J29 | L29: =IF(A26>TODAY(),"upcoming",IF(F29>=J29,"✓ target met",IF(A28>=DATE(YEAR(TODAY()),MONTH(TODAY()),1),"in progress","below target")))
A30: 46569 | B30: =SUMPRODUCT(('My Portfolio'!$J$7:$J$106>=$A30)*('My Portfolio'!$J$7:$J$106<=EOMONTH($A30,0))*('My Portfolio'!$C$7:$C$106<>"Call")*'My Portfolio'!$G$7:$G$106*'My Portfolio'!$F$7:$F$106)-SUMPRODUCT(('My Portfolio'!$M$7:$M$106>=$A30)*('My Portfolio'!$M$7:$M$106<=EOMONTH($A30,0))*('My Portfolio'!$C$7:$C$106<>"Call")*(TRIM('My Portfolio'!$S$7:$S$106)<>"")*('My Portfolio'!$T$7:$T$106="")*'My Portfolio'!$N$7:$N$106*'My Portfolio'!$F$7:$F$106) | C30: =SUMPRODUCT(('My Portfolio'!$J$7:$J$106>=$A30)*('My Portfolio'!$J$7:$J$106<=EOMONTH($A30,0))*('My Portfolio'!$C$7:$C$106="Call")*'My Portfolio'!$G$7:$G$106*'My Portfolio'!$F$7:$F$106)-SUMPRODUCT(('My Portfolio'!$M$7:$M$106>=$A30)*('My Portfolio'!$M$7:$M$106<=EOMONTH($A30,0))*('My Portfolio'!$C$7:$C$106="Call")*(TRIM('My Portfolio'!$S$7:$S$106)<>"")*('My Portfolio'!$T$7:$T$106="")*'My Portfolio'!$N$7:$N$106*'My Portfolio'!$F$7:$F$106) | D30: =SUMIFS('My Portfolio'!$T$7:$T$106,'My Portfolio'!$M$7:$M$106,">="&$A30,'My Portfolio'!$M$7:$M$106,"<="&EOMONTH($A30,0),'My Portfolio'!$C$7:$C$106,"<>Call") | E30: =SUMIFS('My Portfolio'!$T$7:$T$106,'My Portfolio'!$M$7:$M$106,">="&$A30,'My Portfolio'!$M$7:$M$106,"<="&EOMONTH($A30,0),'My Portfolio'!$C$7:$C$106,"Call") | F30: =D30+E30 | G30: =G28+F30 | H30: =COUNTIFS('My Portfolio'!$M$7:$M$106,">="&$A30,'My Portfolio'!$M$7:$M$106,"<="&EOMONTH($A30,0),'My Portfolio'!$T$7:$T$106,">0")+COUNTIFS('My Portfolio'!$M$7:$M$106,">="&$A30,'My Portfolio'!$M$7:$M$106,"<="&EOMONTH($A30,0),'My Portfolio'!$T$7:$T$106,"<=0") | I30: =COUNTIFS('My Portfolio'!$M$7:$M$106,">="&$A30,'My Portfolio'!$M$7:$M$106,"<="&EOMONTH($A30,0),'My Portfolio'!$T$7:$T$106,">0") | J30: ='My Portfolio'!$I$3 | K30: =F30-J30 | L30: =IF($A30>TODAY(),"upcoming",IF(F30>=J30,"✓ target met",IF($A30=DATE(YEAR(TODAY()),MONTH(TODAY()),1),"in progress","below target")))
A31: 46600 | B31: =SUMPRODUCT(('My Portfolio'!$J$7:$J$106>=$A31)*('My Portfolio'!$J$7:$J$106<=EOMONTH($A31,0))*('My Portfolio'!$C$7:$C$106<>"Call")*'My Portfolio'!$G$7:$G$106*'My Portfolio'!$F$7:$F$106)-SUMPRODUCT(('My Portfolio'!$M$7:$M$106>=$A31)*('My Portfolio'!$M$7:$M$106<=EOMONTH($A31,0))*('My Portfolio'!$C$7:$C$106<>"Call")*(TRIM('My Portfolio'!$S$7:$S$106)<>"")*('My Portfolio'!$T$7:$T$106="")*'My Portfolio'!$N$7:$N$106*'My Portfolio'!$F$7:$F$106) | C31: =SUMPRODUCT(('My Portfolio'!$J$7:$J$106>=$A31)*('My Portfolio'!$J$7:$J$106<=EOMONTH($A31,0))*('My Portfolio'!$C$7:$C$106="Call")*'My Portfolio'!$G$7:$G$106*'My Portfolio'!$F$7:$F$106)-SUMPRODUCT(('My Portfolio'!$M$7:$M$106>=$A31)*('My Portfolio'!$M$7:$M$106<=EOMONTH($A31,0))*('My Portfolio'!$C$7:$C$106="Call")*(TRIM('My Portfolio'!$S$7:$S$106)<>"")*('My Portfolio'!$T$7:$T$106="")*'My Portfolio'!$N$7:$N$106*'My Portfolio'!$F$7:$F$106) | D31: =SUMIFS('My Portfolio'!$T$7:$T$106,'My Portfolio'!$M$7:$M$106,">="&$A31,'My Portfolio'!$M$7:$M$106,"<="&EOMONTH($A31,0),'My Portfolio'!$C$7:$C$106,"<>Call") | E31: =SUMIFS('My Portfolio'!$T$7:$T$106,'My Portfolio'!$M$7:$M$106,">="&$A31,'My Portfolio'!$M$7:$M$106,"<="&EOMONTH($A31,0),'My Portfolio'!$C$7:$C$106,"Call") | F31: =D31+E31 | G31: =G30+F31 | H31: =COUNTIFS('My Portfolio'!$M$7:$M$106,">="&$A31,'My Portfolio'!$M$7:$M$106,"<="&EOMONTH($A31,0),'My Portfolio'!$T$7:$T$106,">0")+COUNTIFS('My Portfolio'!$M$7:$M$106,">="&$A31,'My Portfolio'!$M$7:$M$106,"<="&EOMONTH($A31,0),'My Portfolio'!$T$7:$T$106,"<=0") | I31: =COUNTIFS('My Portfolio'!$M$7:$M$106,">="&$A31,'My Portfolio'!$M$7:$M$106,"<="&EOMONTH($A31,0),'My Portfolio'!$T$7:$T$106,">0") | J31: ='My Portfolio'!$I$3 | K31: =F31-J31 | L31: =IF($A31>TODAY(),"upcoming",IF(F31>=J31,"✓ target met",IF($A31=DATE(YEAR(TODAY()),MONTH(TODAY()),1),"in progress","below target")))
A32: 46631 | B32: =SUMPRODUCT(('My Portfolio'!$J$7:$J$106>=$A32)*('My Portfolio'!$J$7:$J$106<=EOMONTH($A32,0))*('My Portfolio'!$C$7:$C$106<>"Call")*'My Portfolio'!$G$7:$G$106*'My Portfolio'!$F$7:$F$106)-SUMPRODUCT(('My Portfolio'!$M$7:$M$106>=$A32)*('My Portfolio'!$M$7:$M$106<=EOMONTH($A32,0))*('My Portfolio'!$C$7:$C$106<>"Call")*(TRIM('My Portfolio'!$S$7:$S$106)<>"")*('My Portfolio'!$T$7:$T$106="")*'My Portfolio'!$N$7:$N$106*'My Portfolio'!$F$7:$F$106) | C32: =SUMPRODUCT(('My Portfolio'!$J$7:$J$106>=$A32)*('My Portfolio'!$J$7:$J$106<=EOMONTH($A32,0))*('My Portfolio'!$C$7:$C$106="Call")*'My Portfolio'!$G$7:$G$106*'My Portfolio'!$F$7:$F$106)-SUMPRODUCT(('My Portfolio'!$M$7:$M$106>=$A32)*('My Portfolio'!$M$7:$M$106<=EOMONTH($A32,0))*('My Portfolio'!$C$7:$C$106="Call")*(TRIM('My Portfolio'!$S$7:$S$106)<>"")*('My Portfolio'!$T$7:$T$106="")*'My Portfolio'!$N$7:$N$106*'My Portfolio'!$F$7:$F$106) | D32: =SUMIFS('My Portfolio'!$T$7:$T$106,'My Portfolio'!$M$7:$M$106,">="&$A32,'My Portfolio'!$M$7:$M$106,"<="&EOMONTH($A32,0),'My Portfolio'!$C$7:$C$106,"<>Call") | E32: =SUMIFS('My Portfolio'!$T$7:$T$106,'My Portfolio'!$M$7:$M$106,">="&$A32,'My Portfolio'!$M$7:$M$106,"<="&EOMONTH($A32,0),'My Portfolio'!$C$7:$C$106,"Call") | F32: =D32+E32 | G32: =G31+F32 | H32: =COUNTIFS('My Portfolio'!$M$7:$M$106,">="&$A32,'My Portfolio'!$M$7:$M$106,"<="&EOMONTH($A32,0),'My Portfolio'!$T$7:$T$106,">0")+COUNTIFS('My Portfolio'!$M$7:$M$106,">="&$A32,'My Portfolio'!$M$7:$M$106,"<="&EOMONTH($A32,0),'My Portfolio'!$T$7:$T$106,"<=0") | I32: =COUNTIFS('My Portfolio'!$M$7:$M$106,">="&$A32,'My Portfolio'!$M$7:$M$106,"<="&EOMONTH($A32,0),'My Portfolio'!$T$7:$T$106,">0") | J32: ='My Portfolio'!$I$3 | K32: =F32-J32 | L32: =IF($A32>TODAY(),"upcoming",IF(F32>=J32,"✓ target met",IF($A32=DATE(YEAR(TODAY()),MONTH(TODAY()),1),"in progress","below target")))
A33: Q3 2027 | B33: =B30+B31+B32 | C33: =C30+C31+C32 | D33: =D30+D31+D32 | E33: =E30+E31+E32 | F33: =F30+F31+F32 | G33: =G32 | H33: =H30+H31+H32 | I33: =I30+I31+I32 | J33: =IF(A30<=TODAY(),J30,0)+IF(A31<=TODAY(),J31,0)+IF(A32<=TODAY(),J32,0) | K33: =F33-J33 | L33: =IF(A30>TODAY(),"upcoming",IF(F33>=J33,"✓ target met",IF(A32>=DATE(YEAR(TODAY()),MONTH(TODAY()),1),"in progress","below target")))
A34: 46661 | B34: =SUMPRODUCT(('My Portfolio'!$J$7:$J$106>=$A34)*('My Portfolio'!$J$7:$J$106<=EOMONTH($A34,0))*('My Portfolio'!$C$7:$C$106<>"Call")*'My Portfolio'!$G$7:$G$106*'My Portfolio'!$F$7:$F$106)-SUMPRODUCT(('My Portfolio'!$M$7:$M$106>=$A34)*('My Portfolio'!$M$7:$M$106<=EOMONTH($A34,0))*('My Portfolio'!$C$7:$C$106<>"Call")*(TRIM('My Portfolio'!$S$7:$S$106)<>"")*('My Portfolio'!$T$7:$T$106="")*'My Portfolio'!$N$7:$N$106*'My Portfolio'!$F$7:$F$106) | C34: =SUMPRODUCT(('My Portfolio'!$J$7:$J$106>=$A34)*('My Portfolio'!$J$7:$J$106<=EOMONTH($A34,0))*('My Portfolio'!$C$7:$C$106="Call")*'My Portfolio'!$G$7:$G$106*'My Portfolio'!$F$7:$F$106)-SUMPRODUCT(('My Portfolio'!$M$7:$M$106>=$A34)*('My Portfolio'!$M$7:$M$106<=EOMONTH($A34,0))*('My Portfolio'!$C$7:$C$106="Call")*(TRIM('My Portfolio'!$S$7:$S$106)<>"")*('My Portfolio'!$T$7:$T$106="")*'My Portfolio'!$N$7:$N$106*'My Portfolio'!$F$7:$F$106) | D34: =SUMIFS('My Portfolio'!$T$7:$T$106,'My Portfolio'!$M$7:$M$106,">="&$A34,'My Portfolio'!$M$7:$M$106,"<="&EOMONTH($A34,0),'My Portfolio'!$C$7:$C$106,"<>Call") | E34: =SUMIFS('My Portfolio'!$T$7:$T$106,'My Portfolio'!$M$7:$M$106,">="&$A34,'My Portfolio'!$M$7:$M$106,"<="&EOMONTH($A34,0),'My Portfolio'!$C$7:$C$106,"Call") | F34: =D34+E34 | G34: =G32+F34 | H34: =COUNTIFS('My Portfolio'!$M$7:$M$106,">="&$A34,'My Portfolio'!$M$7:$M$106,"<="&EOMONTH($A34,0),'My Portfolio'!$T$7:$T$106,">0")+COUNTIFS('My Portfolio'!$M$7:$M$106,">="&$A34,'My Portfolio'!$M$7:$M$106,"<="&EOMONTH($A34,0),'My Portfolio'!$T$7:$T$106,"<=0") | I34: =COUNTIFS('My Portfolio'!$M$7:$M$106,">="&$A34,'My Portfolio'!$M$7:$M$106,"<="&EOMONTH($A34,0),'My Portfolio'!$T$7:$T$106,">0") | J34: ='My Portfolio'!$I$3 | K34: =F34-J34 | L34: =IF($A34>TODAY(),"upcoming",IF(F34>=J34,"✓ target met",IF($A34=DATE(YEAR(TODAY()),MONTH(TODAY()),1),"in progress","below target")))
A35: 46692 | B35: =SUMPRODUCT(('My Portfolio'!$J$7:$J$106>=$A35)*('My Portfolio'!$J$7:$J$106<=EOMONTH($A35,0))*('My Portfolio'!$C$7:$C$106<>"Call")*'My Portfolio'!$G$7:$G$106*'My Portfolio'!$F$7:$F$106)-SUMPRODUCT(('My Portfolio'!$M$7:$M$106>=$A35)*('My Portfolio'!$M$7:$M$106<=EOMONTH($A35,0))*('My Portfolio'!$C$7:$C$106<>"Call")*(TRIM('My Portfolio'!$S$7:$S$106)<>"")*('My Portfolio'!$T$7:$T$106="")*'My Portfolio'!$N$7:$N$106*'My Portfolio'!$F$7:$F$106) | C35: =SUMPRODUCT(('My Portfolio'!$J$7:$J$106>=$A35)*('My Portfolio'!$J$7:$J$106<=EOMONTH($A35,0))*('My Portfolio'!$C$7:$C$106="Call")*'My Portfolio'!$G$7:$G$106*'My Portfolio'!$F$7:$F$106)-SUMPRODUCT(('My Portfolio'!$M$7:$M$106>=$A35)*('My Portfolio'!$M$7:$M$106<=EOMONTH($A35,0))*('My Portfolio'!$C$7:$C$106="Call")*(TRIM('My Portfolio'!$S$7:$S$106)<>"")*('My Portfolio'!$T$7:$T$106="")*'My Portfolio'!$N$7:$N$106*'My Portfolio'!$F$7:$F$106) | D35: =SUMIFS('My Portfolio'!$T$7:$T$106,'My Portfolio'!$M$7:$M$106,">="&$A35,'My Portfolio'!$M$7:$M$106,"<="&EOMONTH($A35,0),'My Portfolio'!$C$7:$C$106,"<>Call") | E35: =SUMIFS('My Portfolio'!$T$7:$T$106,'My Portfolio'!$M$7:$M$106,">="&$A35,'My Portfolio'!$M$7:$M$106,"<="&EOMONTH($A35,0),'My Portfolio'!$C$7:$C$106,"Call") | F35: =D35+E35 | G35: =G34+F35 | H35: =COUNTIFS('My Portfolio'!$M$7:$M$106,">="&$A35,'My Portfolio'!$M$7:$M$106,"<="&EOMONTH($A35,0),'My Portfolio'!$T$7:$T$106,">0")+COUNTIFS('My Portfolio'!$M$7:$M$106,">="&$A35,'My Portfolio'!$M$7:$M$106,"<="&EOMONTH($A35,0),'My Portfolio'!$T$7:$T$106,"<=0") | I35: =COUNTIFS('My Portfolio'!$M$7:$M$106,">="&$A35,'My Portfolio'!$M$7:$M$106,"<="&EOMONTH($A35,0),'My Portfolio'!$T$7:$T$106,">0") | J35: ='My Portfolio'!$I$3 | K35: =F35-J35 | L35: =IF($A35>TODAY(),"upcoming",IF(F35>=J35,"✓ target met",IF($A35=DATE(YEAR(TODAY()),MONTH(TODAY()),1),"in progress","below target")))
A36: 46722 | B36: =SUMPRODUCT(('My Portfolio'!$J$7:$J$106>=$A36)*('My Portfolio'!$J$7:$J$106<=EOMONTH($A36,0))*('My Portfolio'!$C$7:$C$106<>"Call")*'My Portfolio'!$G$7:$G$106*'My Portfolio'!$F$7:$F$106)-SUMPRODUCT(('My Portfolio'!$M$7:$M$106>=$A36)*('My Portfolio'!$M$7:$M$106<=EOMONTH($A36,0))*('My Portfolio'!$C$7:$C$106<>"Call")*(TRIM('My Portfolio'!$S$7:$S$106)<>"")*('My Portfolio'!$T$7:$T$106="")*'My Portfolio'!$N$7:$N$106*'My Portfolio'!$F$7:$F$106) | C36: =SUMPRODUCT(('My Portfolio'!$J$7:$J$106>=$A36)*('My Portfolio'!$J$7:$J$106<=EOMONTH($A36,0))*('My Portfolio'!$C$7:$C$106="Call")*'My Portfolio'!$G$7:$G$106*'My Portfolio'!$F$7:$F$106)-SUMPRODUCT(('My Portfolio'!$M$7:$M$106>=$A36)*('My Portfolio'!$M$7:$M$106<=EOMONTH($A36,0))*('My Portfolio'!$C$7:$C$106="Call")*(TRIM('My Portfolio'!$S$7:$S$106)<>"")*('My Portfolio'!$T$7:$T$106="")*'My Portfolio'!$N$7:$N$106*'My Portfolio'!$F$7:$F$106) | D36: =SUMIFS('My Portfolio'!$T$7:$T$106,'My Portfolio'!$M$7:$M$106,">="&$A36,'My Portfolio'!$M$7:$M$106,"<="&EOMONTH($A36,0),'My Portfolio'!$C$7:$C$106,"<>Call") | E36: =SUMIFS('My Portfolio'!$T$7:$T$106,'My Portfolio'!$M$7:$M$106,">="&$A36,'My Portfolio'!$M$7:$M$106,"<="&EOMONTH($A36,0),'My Portfolio'!$C$7:$C$106,"Call") | F36: =D36+E36 | G36: =G35+F36 | H36: =COUNTIFS('My Portfolio'!$M$7:$M$106,">="&$A36,'My Portfolio'!$M$7:$M$106,"<="&EOMONTH($A36,0),'My Portfolio'!$T$7:$T$106,">0")+COUNTIFS('My Portfolio'!$M$7:$M$106,">="&$A36,'My Portfolio'!$M$7:$M$106,"<="&EOMONTH($A36,0),'My Portfolio'!$T$7:$T$106,"<=0") | I36: =COUNTIFS('My Portfolio'!$M$7:$M$106,">="&$A36,'My Portfolio'!$M$7:$M$106,"<="&EOMONTH($A36,0),'My Portfolio'!$T$7:$T$106,">0") | J36: ='My Portfolio'!$I$3 | K36: =F36-J36 | L36: =IF($A36>TODAY(),"upcoming",IF(F36>=J36,"✓ target met",IF($A36=DATE(YEAR(TODAY()),MONTH(TODAY()),1),"in progress","below target")))
